{"uid":"69169435400c9f0a","name":"Valid login should succeed","fullName":"tests.test_login#test_valid_login","historyId":"27b150db6705ef6511c7ecb21ff68d02","time":{"start":1757364185817,"stop":1757364185817,"duration":0},"status":"broken","statusMessage":"selenium.common.exceptions.WebDriverException: Message: 'chromedriver.exe' executable may have wrong permissions.","statusTrace":"self = <selenium.webdriver.chrome.service.Service object at 0x7fabaaf44980>\npath = '/home/runner/work/selenium-ci-cd/selenium-ci-cd/drivers/chromedriver.exe'\n\n    def _start_process(self, path: str) -> None:\n        \"\"\"Creates a subprocess by executing the command provided.\n    \n        :param cmd: full command to execute\n        \"\"\"\n        cmd = [path]\n        cmd.extend(self.command_line_args())\n        close_file_descriptors = self.popen_kw.pop(\"close_fds\", system() != \"Windows\")\n        try:\n>           self.process = subprocess.Popen(\n                cmd,\n                env=self.env,\n                close_fds=close_file_descriptors,\n                stdout=self.log_output,\n                stderr=self.log_output,\n                stdin=PIPE,\n                creationflags=self.creation_flags,\n                **self.popen_kw,\n            )\n\n/opt/hostedtoolcache/Python/3.13.7/x64/lib/python3.13/site-packages/selenium/webdriver/common/service.py:206: \n_ _ _ _ _ _ _ _ _ _ _ _ _ _ _ _ _ _ _ _ _ _ _ _ _ _ _ _ _ _ _ _ _ _ _ _ _ _ _ _ \n/opt/hostedtoolcache/Python/3.13.7/x64/lib/python3.13/subprocess.py:1039: in __init__\n    self._execute_child(args, executable, preexec_fn, close_fds,\n/opt/hostedtoolcache/Python/3.13.7/x64/lib/python3.13/subprocess.py:1857: in _execute_child\n    self._posix_spawn(args, executable, env, restore_signals, close_fds,\n_ _ _ _ _ _ _ _ _ _ _ _ _ _ _ _ _ _ _ _ _ _ _ _ _ _ _ _ _ _ _ _ _ _ _ _ _ _ _ _ \n\nself = <Popen: returncode: None args: ['/home/runner/work/selenium-ci-cd/selenium-c...>\nargs = ['/home/runner/work/selenium-ci-cd/selenium-ci-cd/drivers/chromedriver.exe', '--port=34739']\nexecutable = '/home/runner/work/selenium-ci-cd/selenium-ci-cd/drivers/chromedriver.exe'\nenv = environ({'SHELL': '/bin/bash', 'SELENIUM_JAR_PATH': '/usr/share/java/selenium-server.jar', 'CONDA': '/usr/share/minico...hostedtoolcache/Python/3.13.7/x64/bin/pytest', 'PYTEST_CURRENT_TEST': 'tests/test_login.py::test_valid_login (setup)'})\nrestore_signals = True, close_fds = True, p2cread = 14, p2cwrite = 15\nc2pread = -1, c2pwrite = 13, errread = -1, errwrite = 13\n\n    def _posix_spawn(self, args, executable, env, restore_signals, close_fds,\n                     p2cread, p2cwrite,\n                     c2pread, c2pwrite,\n                     errread, errwrite):\n        \"\"\"Execute program using os.posix_spawn().\"\"\"\n        kwargs = {}\n        if restore_signals:\n            # See _Py_RestoreSignals() in Python/pylifecycle.c\n            sigset = []\n            for signame in ('SIGPIPE', 'SIGXFZ', 'SIGXFSZ'):\n                signum = getattr(signal, signame, None)\n                if signum is not None:\n                    sigset.append(signum)\n            kwargs['setsigdef'] = sigset\n    \n        file_actions = []\n        for fd in (p2cwrite, c2pread, errread):\n            if fd != -1:\n                file_actions.append((os.POSIX_SPAWN_CLOSE, fd))\n        for fd, fd2 in (\n            (p2cread, 0),\n            (c2pwrite, 1),\n            (errwrite, 2),\n        ):\n            if fd != -1:\n                file_actions.append((os.POSIX_SPAWN_DUP2, fd, fd2))\n    \n        if close_fds:\n            file_actions.append((os.POSIX_SPAWN_CLOSEFROM, 3))\n    \n        if file_actions:\n            kwargs['file_actions'] = file_actions\n    \n>       self.pid = os.posix_spawn(executable, args, env, **kwargs)\nE       PermissionError: [Errno 13] Permission denied: '/home/runner/work/selenium-ci-cd/selenium-ci-cd/drivers/chromedriver.exe'\n\n/opt/hostedtoolcache/Python/3.13.7/x64/lib/python3.13/subprocess.py:1801: PermissionError\n\nThe above exception was the direct cause of the following exception:\n\n    @pytest.fixture(scope=\"function\")\n    def driver():\n        \"\"\"\n        Sets up and tears down the Selenium WebDriver for each test function.\n        \"\"\"\n        opts = get_chrome_options()\n    \n        # We are now using a manual path to the driver.exe file\n        # This assumes you have downloaded chromedriver.exe and placed it in a 'drivers' folder.\n        driver_path = os.path.join(os.getcwd(), 'drivers', 'chromedriver.exe')\n        service = ChromeService(executable_path=driver_path)\n    \n>       driver = webdriver.Chrome(service=service, options=opts)\n\nconftest.py:33: \n_ _ _ _ _ _ _ _ _ _ _ _ _ _ _ _ _ _ _ _ _ _ _ _ _ _ _ _ _ _ _ _ _ _ _ _ _ _ _ _ \n/opt/hostedtoolcache/Python/3.13.7/x64/lib/python3.13/site-packages/selenium/webdriver/chrome/webdriver.py:45: in __init__\n    super().__init__(\n/opt/hostedtoolcache/Python/3.13.7/x64/lib/python3.13/site-packages/selenium/webdriver/chromium/webdriver.py:53: in __init__\n    self.service.start()\n/opt/hostedtoolcache/Python/3.13.7/x64/lib/python3.13/site-packages/selenium/webdriver/common/service.py:105: in start\n    self._start_process(self._path)\n_ _ _ _ _ _ _ _ _ _ _ _ _ _ _ _ _ _ _ _ _ _ _ _ _ _ _ _ _ _ _ _ _ _ _ _ _ _ _ _ \n\nself = <selenium.webdriver.chrome.service.Service object at 0x7fabaaf44980>\npath = '/home/runner/work/selenium-ci-cd/selenium-ci-cd/drivers/chromedriver.exe'\n\n    def _start_process(self, path: str) -> None:\n        \"\"\"Creates a subprocess by executing the command provided.\n    \n        :param cmd: full command to execute\n        \"\"\"\n        cmd = [path]\n        cmd.extend(self.command_line_args())\n        close_file_descriptors = self.popen_kw.pop(\"close_fds\", system() != \"Windows\")\n        try:\n            self.process = subprocess.Popen(\n                cmd,\n                env=self.env,\n                close_fds=close_file_descriptors,\n                stdout=self.log_output,\n                stderr=self.log_output,\n                stdin=PIPE,\n                creationflags=self.creation_flags,\n                **self.popen_kw,\n            )\n            logger.debug(f\"Started executable: `{self._path}` in a child process with pid: {self.process.pid}\")\n        except TypeError:\n            raise\n        except OSError as err:\n            if err.errno == errno.EACCES:\n>               raise WebDriverException(\n                    f\"'{os.path.basename(self._path)}' executable may have wrong permissions.\"\n                ) from err\nE               selenium.common.exceptions.WebDriverException: Message: 'chromedriver.exe' executable may have wrong permissions.\n\n/opt/hostedtoolcache/Python/3.13.7/x64/lib/python3.13/site-packages/selenium/webdriver/common/service.py:221: WebDriverException","flaky":false,"newFailed":false,"newBroken":false,"newPassed":false,"retriesCount":0,"retriesStatusChange":false,"beforeStages":[{"name":"driver","time":{"start":1757364185817,"stop":1757364185818,"duration":1},"status":"broken","statusMessage":"selenium.common.exceptions.WebDriverException: Message: 'chromedriver.exe' executable may have wrong permissions.\n\n","statusTrace":"  File \"/opt/hostedtoolcache/Python/3.13.7/x64/lib/python3.13/site-packages/pluggy/_callers.py\", line 38, in run_old_style_hookwrapper\n    res = yield\n          ^^^^^\n  File \"/opt/hostedtoolcache/Python/3.13.7/x64/lib/python3.13/site-packages/pluggy/_callers.py\", line 139, in _multicall\n    teardown.throw(exception)\n    ~~~~~~~~~~~~~~^^^^^^^^^^^\n  File \"/opt/hostedtoolcache/Python/3.13.7/x64/lib/python3.13/site-packages/pluggy/_callers.py\", line 53, in run_old_style_hookwrapper\n    return result.get_result()\n           ~~~~~~~~~~~~~~~~~^^\n  File \"/opt/hostedtoolcache/Python/3.13.7/x64/lib/python3.13/site-packages/pluggy/_result.py\", line 103, in get_result\n    raise exc.with_traceback(tb)\n  File \"/opt/hostedtoolcache/Python/3.13.7/x64/lib/python3.13/site-packages/pluggy/_callers.py\", line 38, in run_old_style_hookwrapper\n    res = yield\n          ^^^^^\n  File \"/opt/hostedtoolcache/Python/3.13.7/x64/lib/python3.13/site-packages/pluggy/_callers.py\", line 121, in _multicall\n    res = hook_impl.function(*args)\n  File \"/opt/hostedtoolcache/Python/3.13.7/x64/lib/python3.13/site-packages/_pytest/fixtures.py\", line 1123, in pytest_fixture_setup\n    result = call_fixture_func(fixturefunc, request, kwargs)\n  File \"/opt/hostedtoolcache/Python/3.13.7/x64/lib/python3.13/site-packages/_pytest/fixtures.py\", line 895, in call_fixture_func\n    fixture_result = next(generator)\n  File \"/home/runner/work/selenium-ci-cd/selenium-ci-cd/conftest.py\", line 33, in driver\n    driver = webdriver.Chrome(service=service, options=opts)\n  File \"/opt/hostedtoolcache/Python/3.13.7/x64/lib/python3.13/site-packages/selenium/webdriver/chrome/webdriver.py\", line 45, in __init__\n    super().__init__(\n    ~~~~~~~~~~~~~~~~^\n        DesiredCapabilities.CHROME[\"browserName\"],\n        ^^^^^^^^^^^^^^^^^^^^^^^^^^^^^^^^^^^^^^^^^^\n    ...<3 lines>...\n        keep_alive,\n        ^^^^^^^^^^^\n    )\n    ^\n  File \"/opt/hostedtoolcache/Python/3.13.7/x64/lib/python3.13/site-packages/selenium/webdriver/chromium/webdriver.py\", line 53, in __init__\n    self.service.start()\n    ~~~~~~~~~~~~~~~~~~^^\n  File \"/opt/hostedtoolcache/Python/3.13.7/x64/lib/python3.13/site-packages/selenium/webdriver/common/service.py\", line 105, in start\n    self._start_process(self._path)\n    ~~~~~~~~~~~~~~~~~~~^^^^^^^^^^^^\n  File \"/opt/hostedtoolcache/Python/3.13.7/x64/lib/python3.13/site-packages/selenium/webdriver/common/service.py\", line 221, in _start_process\n    raise WebDriverException(\n        f\"'{os.path.basename(self._path)}' executable may have wrong permissions.\"\n    ) from err\n","steps":[],"attachments":[],"parameters":[],"shouldDisplayMessage":true,"stepsCount":0,"attachmentsCount":0,"hasContent":true},{"name":"driver","time":{"start":1757364185932,"stop":1757364185932,"duration":0},"status":"broken","statusMessage":"selenium.common.exceptions.WebDriverException: Message: 'chromedriver.exe' executable may have wrong permissions.\n\n","statusTrace":"  File \"/opt/hostedtoolcache/Python/3.13.7/x64/lib/python3.13/site-packages/pluggy/_callers.py\", line 38, in run_old_style_hookwrapper\n    res = yield\n          ^^^^^\n  File \"/opt/hostedtoolcache/Python/3.13.7/x64/lib/python3.13/site-packages/pluggy/_callers.py\", line 139, in _multicall\n    teardown.throw(exception)\n    ~~~~~~~~~~~~~~^^^^^^^^^^^\n  File \"/opt/hostedtoolcache/Python/3.13.7/x64/lib/python3.13/site-packages/pluggy/_callers.py\", line 53, in run_old_style_hookwrapper\n    return result.get_result()\n           ~~~~~~~~~~~~~~~~~^^\n  File \"/opt/hostedtoolcache/Python/3.13.7/x64/lib/python3.13/site-packages/pluggy/_result.py\", line 103, in get_result\n    raise exc.with_traceback(tb)\n  File \"/opt/hostedtoolcache/Python/3.13.7/x64/lib/python3.13/site-packages/pluggy/_callers.py\", line 38, in run_old_style_hookwrapper\n    res = yield\n          ^^^^^\n  File \"/opt/hostedtoolcache/Python/3.13.7/x64/lib/python3.13/site-packages/pluggy/_callers.py\", line 121, in _multicall\n    res = hook_impl.function(*args)\n  File \"/opt/hostedtoolcache/Python/3.13.7/x64/lib/python3.13/site-packages/_pytest/fixtures.py\", line 1123, in pytest_fixture_setup\n    result = call_fixture_func(fixturefunc, request, kwargs)\n  File \"/opt/hostedtoolcache/Python/3.13.7/x64/lib/python3.13/site-packages/_pytest/fixtures.py\", line 895, in call_fixture_func\n    fixture_result = next(generator)\n  File \"/home/runner/work/selenium-ci-cd/selenium-ci-cd/conftest.py\", line 33, in driver\n    driver = webdriver.Chrome(service=service, options=opts)\n  File \"/opt/hostedtoolcache/Python/3.13.7/x64/lib/python3.13/site-packages/selenium/webdriver/chrome/webdriver.py\", line 45, in __init__\n    super().__init__(\n    ~~~~~~~~~~~~~~~~^\n        DesiredCapabilities.CHROME[\"browserName\"],\n        ^^^^^^^^^^^^^^^^^^^^^^^^^^^^^^^^^^^^^^^^^^\n    ...<3 lines>...\n        keep_alive,\n        ^^^^^^^^^^^\n    )\n    ^\n  File \"/opt/hostedtoolcache/Python/3.13.7/x64/lib/python3.13/site-packages/selenium/webdriver/chromium/webdriver.py\", line 53, in __init__\n    self.service.start()\n    ~~~~~~~~~~~~~~~~~~^^\n  File \"/opt/hostedtoolcache/Python/3.13.7/x64/lib/python3.13/site-packages/selenium/webdriver/common/service.py\", line 105, in start\n    self._start_process(self._path)\n    ~~~~~~~~~~~~~~~~~~~^^^^^^^^^^^^\n  File \"/opt/hostedtoolcache/Python/3.13.7/x64/lib/python3.13/site-packages/selenium/webdriver/common/service.py\", line 221, in _start_process\n    raise WebDriverException(\n        f\"'{os.path.basename(self._path)}' executable may have wrong permissions.\"\n    ) from err\n","steps":[],"attachments":[],"parameters":[],"shouldDisplayMessage":true,"stepsCount":0,"attachmentsCount":0,"hasContent":true}],"afterStages":[],"labels":[{"name":"tag","value":"smoke"},{"name":"parentSuite","value":"tests"},{"name":"suite","value":"test_login"},{"name":"host","value":"pkrvm7jw40e0xgp"},{"name":"thread","value":"2369-MainThread"},{"name":"framework","value":"pytest"},{"name":"language","value":"cpython3"},{"name":"package","value":"tests.test_login"},{"name":"resultFormat","value":"allure2"}],"parameters":[],"links":[],"hidden":false,"retry":false,"extra":{"severity":"normal","retries":[],"categories":[{"name":"Test defects","matchedStatuses":[],"flaky":false}],"tags":["smoke"]},"source":"69169435400c9f0a.json","parameterValues":[]}